<?xml version="1.0" encoding="utf-8"?>
<!-- This URDF was automatically created by SolidWorks to URDF Exporter! Originally created by Stephen Brawner (brawner@gmail.com) 
     Commit Version: 1.6.0-4-g7f85cfe  Build Version: 1.6.7995.38578
     For more information, please see http://wiki.ros.org/sw_urdf_exporter -->
<robot
  name="humanoid_description">
  <link
    name="chest_link">
    <inertial>
      <origin
        xyz="-8.28293679618886E-05 0.00245095349909037 -0.0400554897853038"
        rpy="0 0 0" />
      <mass
        value="3.6222448891911" />
      <inertia
        ixx="0.00927736621449688"
        ixy="5.4183285357689E-06"
        ixz="-8.1587912127408E-06"
        iyy="0.0068269139110782"
        iyz="2.81661094771366E-05"
        izz="0.00659637371781693" />
    </inertial>
    <visual>
      <origin
        xyz="0 0 0"
        rpy="0 0 0" />
      <geometry>
        <mesh
          filename="package://humanoid_description/meshes/base_link.STL" />
      </geometry>
      <material
        name="">
        <color
          rgba="0.752941176470588 0.752941176470588 0.752941176470588 1" />
      </material>
    </visual>
    <collision>
      <origin
        xyz="0 0 0"
        rpy="0 0 0" />
      <geometry>
        <mesh
          filename="package://humanoid_description/meshes/base_link.STL" />
      </geometry>
    </collision>
  </link>
  <link
    name="link1">
    <inertial>
      <origin
        xyz="-0.0728434544984589 4.19142224609348E-05 -0.116189406983065"
        rpy="0 0 0" />
      <mass
        value="4.01130857217461" />
      <inertia
        ixx="0.00549719316458641"
        ixy="2.72266840238933E-06"
        ixz="-0.000275818830944953"
        iyy="0.00344725687710746"
        iyz="-4.83377004397469E-06"
        izz="0.00309978532231872" />
    </inertial>
    <visual>
      <origin
        xyz="0 0 0"
        rpy="0 0 0" />
      <geometry>
        <mesh
          filename="package://humanoid_description/meshes/link1.STL" />
      </geometry>
      <material
        name="">
        <color
          rgba="0.752941176470588 0.752941176470588 0.752941176470588 1" />
      </material>
    </visual>
    <collision>
      <origin
        xyz="0 0 0"
        rpy="0 0 0" />
      <geometry>
        <mesh
          filename="package://humanoid_description/meshes/link1.STL" />
      </geometry>
    </collision>
  </link>
  <joint
    name="joint1"
    type="revolute">
    <origin
      xyz="0 0.111 0"
      rpy="1.5708 0 0" />
    <parent
      link="chest_link" />
    <child
      link="link1" />
    <axis
      xyz="0 0 1" />
    <limit
      lower="-3"
      upper="3"
      effort="0"
      velocity="0" />
  </joint>
  <link
    name="link2">
    <inertial>
      <origin
        xyz="0.000674554136897957 -7.98707268084842E-05 0.0611451747770943"
        rpy="0 0 0" />
      <mass
        value="1.83896451263237" />
      <inertia
        ixx="0.00130997269012774"
        ixy="-2.52148752381525E-06"
        ixz="-2.9497450008976E-05"
        iyy="0.00136283021362173"
        iyz="6.56080458221765E-06"
        izz="0.00127826257199311" />
    </inertial>
    <visual>
      <origin
        xyz="0 0 0"
        rpy="0 0 0" />
      <geometry>
        <mesh
          filename="package://humanoid_description/meshes/link2.STL" />
      </geometry>
      <material
        name="">
        <color
          rgba="0.752941176470588 0.752941176470588 0.752941176470588 1" />
      </material>
    </visual>
    <collision>
      <origin
        xyz="0 0 0"
        rpy="0 0 0" />
      <geometry>
        <mesh
          filename="package://humanoid_description/meshes/link2.STL" />
      </geometry>
    </collision>
  </link>
  <joint
    name="joint2"
    type="revolute">
    <origin
      xyz="0 0.065 -0.12"
      rpy="0 0 0" />
    <parent
      link="link1" />
    <child
      link="link2" />
    <axis
      xyz="1 0 0" />
    <limit
      lower="-3"
      upper="3"
      effort="0"
      velocity="0" />
  </joint>
  <link
    name="link3">
    <inertial>
      <origin
        xyz="0.00146790465106376 0.00300000000000006 0.0135654067812014"
        rpy="0 0 0" />
      <mass
        value="0.138996037602082" />
      <inertia
        ixx="0.000167643562788158"
        ixy="1.47057028258303E-19"
        ixz="-8.86208732105541E-06"
        iyy="0.000299255663714549"
        iyz="-1.90919704350535E-20"
        izz="0.00021142987879861" />
    </inertial>
    <visual>
      <origin
        xyz="0 0 0"
        rpy="0 0 0" />
      <geometry>
        <mesh
          filename="package://humanoid_description/meshes/link3.STL" />
      </geometry>
      <material
        name="">
        <color
          rgba="0.898039215686275 0.917647058823529 0.929411764705882 1" />
      </material>
    </visual>
    <collision>
      <origin
        xyz="0 0 0"
        rpy="0 0 0" />
      <geometry>
        <mesh
          filename="package://humanoid_description/meshes/link3.STL" />
      </geometry>
    </collision>
  </link>
  <joint
    name="joint3"
    type="revolute">
    <origin
      xyz="0 0 0"
      rpy="3.1416 0 1.5708" />
    <parent
      link="link2" />
    <child
      link="link3" />
    <axis
      xyz="0 0 1" />
    <limit
      lower="-3"
      upper="3"
      effort="0"
      velocity="0" />
  </joint>
  <link
    name="link4">
    <inertial>
      <origin
        xyz="0.068079854468498 -0.00841217862527573 -0.000217594704341859"
        rpy="0 0 0" />
      <mass
        value="6.77292310387962" />
      <inertia
        ixx="0.0053553058691625"
        ixy="3.63771461334271E-06"
        ixz="7.70199358196544E-05"
        iyy="0.00895648949029985"
        iyz="-2.80338942122995E-06"
        izz="0.00681492065848877" />
    </inertial>
    <visual>
      <origin
        xyz="0 0 0"
        rpy="0 0 0" />
      <geometry>
        <mesh
          filename="package://humanoid_description/meshes/link4.STL" />
      </geometry>
      <material
        name="">
        <color
          rgba="0.752941176470588 0.752941176470588 0.752941176470588 1" />
      </material>
    </visual>
    <collision>
      <origin
        xyz="0 0 0"
        rpy="0 0 0" />
      <geometry>
        <mesh
          filename="package://humanoid_description/meshes/link4.STL" />
      </geometry>
    </collision>
  </link>
  <joint
    name="joint4"
    type="revolute">
    <origin
      xyz="0 0.003 0.05"
      rpy="1.5667 -1.5708 0" />
    <parent
      link="link3" />
    <child
      link="link4" />
    <axis
      xyz="0 0.99999 -0.0041068" />
    <limit
      lower="-3"
      upper="3"
      effort="0"
      velocity="0" />
  </joint>
  <link
    name="link5">
    <inertial>
      <origin
        xyz="0.160102551038823 0.000457350145105207 -0.00865375901396317"
        rpy="0 0 0" />
      <mass
        value="0.656738353244321" />
      <inertia
        ixx="0.000233874118922673"
        ixy="3.53165224336002E-06"
        ixz="2.16391215308251E-09"
        iyy="0.00174493115545611"
        iyz="8.70897215953489E-09"
        izz="0.00193811132241233" />
    </inertial>
    <visual>
      <origin
        xyz="0 0 0"
        rpy="0 0 0" />
      <geometry>
        <mesh
          filename="package://humanoid_description/meshes/link5.STL" />
      </geometry>
      <material
        name="">
        <color
          rgba="0.752941176470588 0.752941176470588 0.752941176470588 1" />
      </material>
    </visual>
    <collision>
      <origin
        xyz="0 0 0"
        rpy="0 0 0" />
      <geometry>
        <mesh
          filename="package://humanoid_description/meshes/link5.STL" />
      </geometry>
    </collision>
  </link>
  <joint
    name="joint5"
    type="revolute">
    <origin
      xyz="0.317 0 0"
      rpy="-1.5749 0 0" />
    <parent
      link="link4" />
    <child
      link="link5" />
    <axis
      xyz="0 0 1" />
    <limit
      lower="-3"
      upper="3"
      effort="0"
      velocity="0" />
  </joint>
  <link
    name="link6">
    <inertial>
      <origin
        xyz="3.69282989604036E-10 -2.58542243170012E-09 0.00865001083659624"
        rpy="0 0 0" />
      <mass
        value="0.0405476705231489" />
      <inertia
        ixx="7.90323317140378E-06"
        ixy="3.64342320493557E-15"
        ixz="1.7843211279735E-12"
        iyy="7.51103795693389E-06"
        iyz="4.94677657785183E-13"
        izz="3.56410737465162E-06" />
    </inertial>
    <visual>
      <origin
        xyz="0 0 0"
        rpy="0 0 0" />
      <geometry>
        <mesh
          filename="package://humanoid_description/meshes/link6.STL" />
      </geometry>
      <material
        name="">
        <color
          rgba="0.898039215686275 0.917647058823529 0.929411764705882 1" />
      </material>
    </visual>
    <collision>
      <origin
        xyz="0 0 0"
        rpy="0 0 0" />
      <geometry>
        <mesh
          filename="package://humanoid_description/meshes/link6.STL" />
      </geometry>
    </collision>
  </link>
  <joint
    name="joint6"
    type="revolute">
    <origin
      xyz="0.373 0 0"
      rpy="-3.1416 0 1.5708" />
    <parent
      link="link5" />
    <child
      link="link6" />
    <axis
      xyz="0 0 1" />
    <limit
      lower="-3"
      upper="3"
      effort="0"
      velocity="0" />
  </joint>
  <link
    name="link7">
    <inertial>
      <origin
        xyz="0.0199754227606495 0.00864999999990936 -0.0354657161472895"
        rpy="0 0 0" />
      <mass
        value="0.144339298666143" />
      <inertia
        ixx="4.01687098929373E-05"
        ixy="2.54118580061172E-18"
        ixz="-3.79536043980265E-06"
        iyy="0.000258843457882055"
        iyz="-5.84163087956415E-20"
        izz="0.000282296824497863" />
    </inertial>
    <visual>
      <origin
        xyz="0 0 0"
        rpy="0 0 0" />
      <geometry>
        <mesh
          filename="package://humanoid_description/meshes/link7.STL" />
      </geometry>
      <material
        name="">
        <color
          rgba="0.752941176470588 0.752941176470588 0.752941176470588 1" />
      </material>
    </visual>
    <collision>
      <origin
        xyz="0 0 0"
        rpy="0 0 0" />
      <geometry>
        <mesh
          filename="package://humanoid_description/meshes/link7.STL" />
      </geometry>
    </collision>
  </link>
  <joint
    name="joint7"
    type="revolute">
    <origin
      xyz="0 0 0"
      rpy="1.5708 0 0" />
    <parent
      link="link6" />
    <child
      link="link7" />
    <axis
      xyz="1 0 0" />
    <limit
      lower="-3"
      upper="3"
      effort="0"
      velocity="0" />
  </joint>
  <link
    name="link8">
    <inertial>
      <origin
        xyz="0.000674554136897979 -7.98707268086368E-05 0.0611451747770972"
        rpy="0 0 0" />
      <mass
        value="1.83896451263238" />
      <inertia
        ixx="0.00130997269012774"
        ixy="-2.521487523817E-06"
        ixz="-2.94974500089755E-05"
        iyy="0.00136283021362174"
        iyz="6.56080458221212E-06"
        izz="0.00127826257199312" />
    </inertial>
    <visual>
      <origin
        xyz="0 0 0"
        rpy="0 0 0" />
      <geometry>
        <mesh
          filename="package://humanoid_description/meshes/link8.STL" />
      </geometry>
      <material
        name="">
        <color
          rgba="0.752941176470588 0.752941176470588 0.752941176470588 1" />
      </material>
    </visual>
    <collision>
      <origin
        xyz="0 0 0"
        rpy="0 0 0" />
      <geometry>
        <mesh
          filename="package://humanoid_description/meshes/link8.STL" />
      </geometry>
    </collision>
  </link>
  <joint
    name="joint8"
    type="revolute">
    <origin
      xyz="0 -0.065 -0.12"
      rpy="0 0 0" />
    <parent
      link="link1" />
    <child
      link="link8" />
    <axis
      xyz="1 0 0" />
    <limit
      lower="-3"
      upper="3"
      effort="0"
      velocity="0" />
  </joint>
  <link
    name="link9">
    <inertial>
      <origin
        xyz="0.00146790465106367 -0.00300000000000037 0.0135654067811973"
        rpy="0 0 0" />
      <mass
        value="0.138996037602082" />
      <inertia
        ixx="0.000167643562788158"
        ixy="1.19046518291902E-19"
        ixz="-8.8620873210554E-06"
        iyy="0.000299255663714548"
        iyz="-1.59095887874616E-20"
        izz="0.000211429878798609" />
    </inertial>
    <visual>
      <origin
        xyz="0 0 0"
        rpy="0 0 0" />
      <geometry>
        <mesh
          filename="package://humanoid_description/meshes/link9.STL" />
      </geometry>
      <material
        name="">
        <color
          rgba="0.898039215686275 0.917647058823529 0.929411764705882 1" />
      </material>
    </visual>
    <collision>
      <origin
        xyz="0 0 0"
        rpy="0 0 0" />
      <geometry>
        <mesh
          filename="package://humanoid_description/meshes/link9.STL" />
      </geometry>
    </collision>
  </link>
  <joint
    name="joint9"
    type="revolute">
    <origin
      xyz="0 0 0"
      rpy="3.1416 0 -1.5708" />
    <parent
      link="link8" />
    <child
      link="link9" />
    <axis
      xyz="0 0 1" />
    <limit
      lower="-3"
      upper="3"
      effort="0"
      velocity="0" />
  </joint>
  <link
    name="link10">
    <inertial>
      <origin
        xyz="0.0679580308029274 0.0084112140687064 -0.000977595595389468"
        rpy="0 0 0" />
      <mass
        value="6.77292310387962" />
      <inertia
        ixx="0.0053582396642984"
        ixy="3.93464481434201E-06"
        ixz="8.74297913019507E-05"
        iyy="0.00895647639661024"
        iyz="1.40455649327707E-06"
        izz="0.00681199995704249" />
    </inertial>
    <visual>
      <origin
        xyz="0 0 0"
        rpy="0 0 0" />
      <geometry>
        <mesh
          filename="package://humanoid_description/meshes/link10.STL" />
      </geometry>
      <material
        name="">
        <color
          rgba="0.752941176470588 0.752941176470588 0.752941176470588 1" />
      </material>
    </visual>
    <collision>
      <origin
        xyz="0 0 0"
        rpy="0 0 0" />
      <geometry>
        <mesh
          filename="package://humanoid_description/meshes/link10.STL" />
      </geometry>
    </collision>
  </link>
  <joint
    name="joint10"
    type="revolute">
    <origin
      xyz="0 -0.003 0.05"
      rpy="3.1416 -1.5605 1.5708" />
    <parent
      link="link9" />
    <child
      link="link10" />
    <axis
      xyz="0 1 0" />
    <limit
      lower="-3"
      upper="3"
      effort="0"
      velocity="0" />
  </joint>
  <link
    name="link11">
    <inertial>
      <origin
        xyz="0.160102551038827 0.000457350145114362 0.0086462409860318"
        rpy="0 0 0" />
      <mass
        value="0.656738353244321" />
      <inertia
        ixx="0.000233874118922674"
        ixy="3.53165224327244E-06"
        ixz="2.16391215324514E-09"
        iyy="0.00174493115545611"
        iyz="8.70897215959495E-09"
        izz="0.00193811132241233" />
    </inertial>
    <visual>
      <origin
        xyz="0 0 0"
        rpy="0 0 0" />
      <geometry>
        <mesh
          filename="package://humanoid_description/meshes/link11.STL" />
      </geometry>
      <material
        name="">
        <color
          rgba="0.752941176470588 0.752941176470588 0.752941176470588 1" />
      </material>
    </visual>
    <collision>
      <origin
        xyz="0 0 0"
        rpy="0 0 0" />
      <geometry>
        <mesh
          filename="package://humanoid_description/meshes/link11.STL" />
      </geometry>
    </collision>
  </link>
  <joint
    name="joint11"
    type="revolute">
    <origin
      xyz="0.31698 0 -0.0032702"
      rpy="-1.5708 0.010316 0" />
    <parent
      link="link10" />
    <child
      link="link11" />
    <axis
      xyz="0 0 1" />
    <limit
      lower="-3"
      upper="3"
      effort="0"
      velocity="0" />
  </joint>
  <link
    name="link12">
    <inertial>
      <origin
        xyz="3.69283013022803E-10 -2.58542354192315E-09 -0.00864998916340047"
        rpy="0 0 0" />
      <mass
        value="0.040547670523149" />
      <inertia
        ixx="7.90323317140379E-06"
        ixy="3.64341020522476E-15"
        ixz="1.78432113059311E-12"
        iyy="7.5110379569339E-06"
        iyz="4.94677657458429E-13"
        izz="3.56410737465161E-06" />
    </inertial>
    <visual>
      <origin
        xyz="0 0 0"
        rpy="0 0 0" />
      <geometry>
        <mesh
          filename="package://humanoid_description/meshes/link12.STL" />
      </geometry>
      <material
        name="">
        <color
          rgba="0.898039215686275 0.917647058823529 0.929411764705882 1" />
      </material>
    </visual>
    <collision>
      <origin
        xyz="0 0 0"
        rpy="0 0 0" />
      <geometry>
        <mesh
          filename="package://humanoid_description/meshes/link12.STL" />
      </geometry>
    </collision>
  </link>
  <joint
    name="joint12"
    type="revolute">
    <origin
      xyz="0.373 0 0"
      rpy="-3.1416 0 1.5708" />
    <parent
      link="link11" />
    <child
      link="link12" />
    <axis
      xyz="0 0 1" />
    <limit
      lower="-3"
      upper="3"
      effort="0"
      velocity="0" />
  </joint>
  <link
    name="link13">
    <inertial>
      <origin
        xyz="0.0199754227606124 -0.00865000000005162 -0.0354657161472758"
        rpy="0 0 0" />
      <mass
        value="0.144339298666143" />
      <inertia
        ixx="4.01687098929373E-05"
        ixy="2.45617541501818E-18"
        ixz="-3.79536043980261E-06"
        iyy="0.000258843457882055"
        iyz="-6.30931755640207E-20"
        izz="0.000282296824497863" />
    </inertial>
    <visual>
      <origin
        xyz="0 0 0"
        rpy="0 0 0" />
      <geometry>
        <mesh
          filename="package://humanoid_description/meshes/link13.STL" />
      </geometry>
      <material
        name="">
        <color
          rgba="0.752941176470588 0.752941176470588 0.752941176470588 1" />
      </material>
    </visual>
    <collision>
      <origin
        xyz="0 0 0"
        rpy="0 0 0" />
      <geometry>
        <mesh
          filename="package://humanoid_description/meshes/link13.STL" />
      </geometry>
    </collision>
  </link>
  <joint
    name="joint13"
    type="revolute">
    <origin
      xyz="0 0 0"
      rpy="1.5708 0 0" />
    <parent
      link="link12" />
    <child
      link="link13" />
    <axis
      xyz="1 0 0" />
    <limit
      lower="-3"
      upper="3"
      effort="0"
      velocity="0" />
  </joint>
</robot>